Workbook

Sheet RESULTS
A1: Table 1
B2: n real 384 | C2: n 384 | D2: n 3000 | E2: n 5000 | F2: n 7000 | G2: n 9000 | H2: n 10677 | J2: ml 384 sp0 | K2: ml 3000 sp0 | L2: ml 5000 sp0 | M2: ml 7000 sp0 | N2: ml 9000 sp0 | O2: ml 10677 sp0 | P2: ml 10677 sp10 | Q2: ml 10677 sp20 | R2: ml 10677 sp30 | S2: ml 10677 sp40 | T2: ml 10677 sp50 | U2: ml 10677 sp60 | V2: ml 10677 sp70 | W2: ml 10677 sp80 | X2: ml 10677 sp90 | Y2: ml 10677 sp98 | Z2: ml real 10677 sp98
B3: CHROMA_NN100 | H3: CHROMA_NN100 | J3: CHROMA_NN100 | Z3: CHROMA_NN100
B4: news_real_embedings_s69878 | C4: gen_news_s69878_d384_sp0 | D4: gen_news_s69878_d3000_sp0 | E4: gen_news_s69878_d5000_sp0 | F4: gen_news_s69878_d7000_sp0 | G4: gen_news_s69878_d9000_sp0 | H4: gen_news_s69878_d10677_sp0 | J4: gen_ml_s69878_d384_sp0 | K4: gen_ml_s69878_d3000_sp0 | L4: gen_ml_s69878_d5000_sp0 | M4: gen_ml_s69878_d7000_sp0 | N4: gen_ml_s69878_d9000_sp0 | O4: gen_ml_s69878_d10677_sp0 | P4: gen_ml_s69878_d10677_sp10 | Q4: gen_ml_s69878_d10677_sp20 | R4: gen_ml_s69878_d10677_sp30 | S4: gen_ml_s69878_d10677_sp40 | T4: gen_ml_s69878_d10677_sp50 | U4: gen_ml_s69878_d10677_sp60 | V4: gen_ml_s69878_d10677_sp70 | W4: gen_ml_s69878_d10677_sp80 | X4: gen_ml_s69878_d10677_sp90 | Y4: gen_ml_s69878_d10677_sp98 | Z4: ml_real_pivoted_na_s69878
B5: inp_file='test_news_s600_d384_sp0.csv' | C5: inp_file='test_news_s600_d384_sp0.csv' | D5: inp_file='test_news_s600_d3000_sp0.csv' | E5: inp_file='test_news_s600_d5000_sp0.csv' | F5: inp_file='test_news_s600_d7000_sp0.csv' | G5: inp_file='test_news_s600_d9000_sp0.csv' | H5: inp_file='test_news_s600_d10677_sp0.csv' | J5: inp_file='test_ml_s600_d384_sp0.csv' | K5: inp_file='test_ml_s600_d3000_sp0.csv' | L5: inp_file='test_ml_s600_d5000_sp0.csv' | M5: inp_file='test_ml_s600_d7000_sp0.csv' | N5: inp_file='test_ml_s600_d9000_sp0.csv' | O5: inp_file='test_ml_s600_d10677_sp0.csv' | P5: inp_file='test_ml_s600_d10677_sp0.csv' | Q5: inp_file='test_ml_s600_d10677_sp0.csv' | R5: inp_file='test_ml_s600_d10677_sp0.csv' | S5: inp_file='test_ml_s600_d10677_sp0.csv' | T5: inp_file='test_ml_s600_d10677_sp0.csv' | U5: inp_file='test_ml_s600_d10677_sp0.csv' | V5: inp_file='test_ml_s600_d10677_sp0.csv' | W5: inp_file='test_ml_s600_d10677_sp0.csv' | X5: inp_file='test_ml_s600_d10677_sp0.csv' | Y5: inp_file='test_ml_s600_d10677_sp0.csv' | Z5: inp_file='test_ml_s600_d10677_sp0.csv'
A6: 0 | B6: 1.0162511 | C6: 1.041187 | D6: 3.2039649 | E6: 3.753813 | F6: 4.6522219 | G6: 7.9514639 | H6: 9.1006873 | J6: 1.0279121 | K6: 2.6773639 | L6: 3.7095289 | M6: 4.5550089 | N6: 6.446594 | O6: 9.272728 | P6: 6.4017608 | Q6: 7.2020712 | R6: 10.107623 | S6: 8.8766563 | T6: 9.9363911 | U6: 7.8772149 | V6: 8.9525011 | W6: 9.614598 | X6: 10.306685 | Y6: 8.4126279 | Z6: 5.895076
A7: 1 | B7: 0.3223362 | C7: 0.36156082 | D7: 0.88841391 | E7: 1.102612 | F7: 1.275723 | G7: 1.7022181 | H7: 2.0299969 | J7: 0.39941096 | K7: 0.72944212 | L7: 1.0136561 | M7: 1.2106161 | N7: 1.6214609 | O7: 2.0804849 | P7: 1.6857359 | Q7: 1.8634458 | R7: 2.1892228 | S7: 2.0671911 | T7: 2.1931708 | U7: 1.946018 | V7: 2.4390631 | W7: 2.3160841 | X7: 2.3449881 | Y7: 2.2450871 | Z7: 0.93085408
A8: 2 | B8: 0.31631088 | C8: 0.36437106 | D8: 1.0548751 | E8: 1.0673859 | F8: 1.2596359 | G8: 1.6178398 | H8: 2.2961738 | J8: 0.40310884 | K8: 0.71185684 | L8: 0.96672916 | M8: 1.2117798 | N8: 1.60572 | O8: 1.9372349 | P8: 1.6695299 | Q8: 1.8349469 | R8: 1.9442823 | S8: 1.984292 | T8: 2.0309031 | U8: 1.891398 | V8: 1.9675021 | W8: 2.142457 | X8: 1.9982951 | Y8: 2.0994639 | Z8: 0.84003568
A9: 3 | B9: 0.31699419 | C9: 0.36489701 | D9: 0.77689719 | E9: 1.01196 | F9: 1.2724972 | G9: 1.6107152 | H9: 1.5648718 | J9: 0.45422626 | K9: 0.70620775 | L9: 0.96407509 | M9: 1.247143 | N9: 1.5352652 | O9: 1.8218522 | P9: 1.6665921 | Q9: 1.7384439 | R9: 1.8446531 | S9: 1.9854059 | T9: 1.9561594 | U9: 1.8742712 | V9: 1.9279671 | W9: 1.9593222 | X9: 2.1413822 | Y9: 1.931169 | Z9: 0.81713176
A10: 4 | B10: 0.3118248 | C10: 0.36478996 | D10: 0.7616961 | E10: 1.0107689 | F10: 1.270606 | G10: 1.6118729 | H10: 1.585043 | J10: 0.41087198 | K10: 0.71099305 | L10: 0.96536183 | M10: 1.210187 | N10: 1.5439727 | O10: 1.7936692 | P10: 1.7182889 | Q10: 1.7208841 | R10: 1.8085392 | S10: 1.8918879 | T10: 1.931216 | U10: 1.8381228 | V10: 1.9679148 | W10: 1.9313781 | X10: 2.0058959 | Y10: 1.7990851 | Z10: 0.81175399
A11: 5 | B11: 0.31072402 | C11: 0.34864688 | D11: 0.75295591 | E11: 1.0528901 | F11: 1.3139987 | G11: 1.580343 | H11: 1.8753531 | J11: 0.34735513 | K11: 0.71390319 | L11: 0.97186899 | M11: 1.2041528 | N11: 1.5511849 | O11: 1.7616651 | P11: 1.6657629 | Q11: 2.2501791 | R11: 1.7580171 | S11: 1.8430429 | T11: 1.88974 | U11: 1.8423128 | V11: 1.8988249 | W11: 1.9806342 | X11: 3.1156113 | Y11: 1.8121519 | Z11: 0.82955694
A12: avg | B12: =AVERAGE(B7:B11) -> 0.31563802 | C12: =AVERAGE(C7:C11) -> 0.36085315 | D12: =AVERAGE(D7:D11) -> 0.84696765 | E12: =AVERAGE(E7:E11) -> 1.0491234 | F12: =AVERAGE(F7:F11) -> 1.2784922 | G12: =AVERAGE(G7:G11) -> 1.6245978 | H12: =AVERAGE(H7:H11) -> 1.8702877 | J12: =AVERAGE(J7:J11) -> 0.40299463 | K12: =AVERAGE(K7:K11) -> 0.71448059 | L12: =AVERAGE(L7:L11) -> 0.97633824 | M12: =AVERAGE(M7:M11) -> 1.2167758 | N12: =AVERAGE(N7:N11) -> 1.5715208 | O12: =AVERAGE(O7:O11) -> 1.8789813 | P12: =AVERAGE(P7:P11) -> 1.681182 | Q12: =AVERAGE(Q7:Q11) -> 1.8815799 | ... Z12: =AVERAGE(Z7:Z11) -> 0.84586649
A13: СІ 95% | B13: =_xlfn.CONFIDENCE.T(0.05, B14, 5) -> 0.0057521875 | C13: =_xlfn.CONFIDENCE.T(0.05, C14, 5) -> 0.008640966 | D13: =_xlfn.CONFIDENCE.T(0.05, D14, 5) -> 0.15944947 | E13: =_xlfn.CONFIDENCE.T(0.05, E14, 5) -> 0.048332973 | F13: =_xlfn.CONFIDENCE.T(0.05, F14, 5) -> 0.025763189 | G13: =_xlfn.CONFIDENCE.T(0.05, G14, 5) -> 0.056844999 | H13: =_xlfn.CONFIDENCE.T(0.05, H14, 5) -> 0.38348884 | J13: =_xlfn.CONFIDENCE.T(0.05, J14, 5) -> 0.047262167 | K13: =_xlfn.CONFIDENCE.T(0.05, K14, 5) -> 0.010960236 | L13: =_xlfn.CONFIDENCE.T(0.05, L14, 5) -> 0.026162015 | M13: =_xlfn.CONFIDENCE.T(0.05, M14, 5) -> 0.021396851 | N13: =_xlfn.CONFIDENCE.T(0.05, N14, 5) -> 0.048688892 | O13: =_xlfn.CONFIDENCE.T(0.05, O14, 5) -> 0.16225244 | P13: =_xlfn.CONFIDENCE.T(0.05, P14, 5) -> 0.027653481 | Q13: =_xlfn.CONFIDENCE.T(0.05, Q14, 5) -> 0.26679882 | ... Z13: =_xlfn.CONFIDENCE.T(0.05, Z14, 5) -> 0.060550182
A14: dev | B14: =_xlfn.STDEV.S(B7:B11) -> 0.0046326442 | C14: =_xlfn.STDEV.S(C7:C11) -> 0.0069591822 | D14: =_xlfn.STDEV.S(D7:D11) -> 0.12841595 | E14: =_xlfn.STDEV.S(E7:E11) -> 0.038925968 | F14: =_xlfn.STDEV.S(F7:F11) -> 0.020748921 | G14: =_xlfn.STDEV.S(G7:G11) -> 0.045781306 | H14: =_xlfn.STDEV.S(H7:H11) -> 0.30885073 | J14: =_xlfn.STDEV.S(J7:J11) -> 0.038063572 | K14: =_xlfn.STDEV.S(K7:K11) -> 0.0088270548 | L14: =_xlfn.STDEV.S(L7:L11) -> 0.021070124 | M14: =_xlfn.STDEV.S(M7:M11) -> 0.017232401 | N14: =_xlfn.STDEV.S(N7:N11) -> 0.039212614 | O14: =_xlfn.STDEV.S(O7:O11) -> 0.13067339 | P14: =_xlfn.STDEV.S(P7:P11) -> 0.022271307 | Q14: =_xlfn.STDEV.S(Q7:Q11) -> 0.21487199 | ... Z14: =_xlfn.STDEV.S(Z7:Z11) -> 0.048765352
A15: min | B15: =MIN(B7:B11) -> 0.31072402 | C15: =MIN(C7:C11) -> 0.34864688 | D15: =MIN(D7:D11) -> 0.75295591 | E15: =MIN(E7:E11) -> 1.0107689 | F15: =MIN(F7:F11) -> 1.2596359 | G15: =MIN(G7:G11) -> 1.580343 | H15: =MIN(H7:H11) -> 1.5648718 | J15: =MIN(J7:J11) -> 0.34735513 | K15: =MIN(K7:K11) -> 0.70620775 | L15: =MIN(L7:L11) -> 0.96407509 | M15: =MIN(M7:M11) -> 1.2041528 | N15: =MIN(N7:N11) -> 1.5352652 | O15: =MIN(O7:O11) -> 1.7616651 | P15: =MIN(P7:P11) -> 1.6657629 | Q15: =MIN(Q7:Q11) -> 1.7208841 | ... Z15: =MIN(Z7:Z11) -> 0.81175399
A16: max | B16: =MAX(B7:B11) -> 0.3223362 | C16: =MAX(C7:C11) -> 0.36489701 | D16: =MAX(D7:D11) -> 1.0548751 | E16: =MAX(E7:E11) -> 1.102612 | F16: =MAX(F7:F11) -> 1.3139987 | G16: =MAX(G7:G11) -> 1.7022181 | H16: =MAX(H7:H11) -> 2.2961738 | J16: =MAX(J7:J11) -> 0.45422626 | K16: =MAX(K7:K11) -> 0.72944212 | L16: =MAX(L7:L11) -> 1.0136561 | M16: =MAX(M7:M11) -> 1.247143 | N16: =MAX(N7:N11) -> 1.6214609 | O16: =MAX(O7:O11) -> 2.0804849 | P16: =MAX(P7:P11) -> 1.7182889 | Q16: =MAX(Q7:Q11) -> 2.2501791 | ... Z16: =MAX(Z7:Z11) -> 0.93085408
B18: CHROMA_NN2500 | H18: CHROMA_NN2500 | J18: CHROMA_NN2500 | Z18: CHROMA_NN2500
B19: news_real_embedings_s69878 | C19: gen_news_s69878_d384_sp0 | D19: gen_news_s69878_d3000_sp0 | E19: gen_news_s69878_d5000_sp0 | F19: gen_news_s69878_d7000_sp0 | G19: gen_news_s69878_d9000_sp0 | H19: gen_news_s69878_d10677_sp0 | J19: gen_ml_s69878_d384_sp0 | K19: gen_ml_s69878_d3000_sp0 | L19: gen_ml_s69878_d5000_sp0 | M19: gen_ml_s69878_d7000_sp0 | N19: gen_ml_s69878_d9000_sp0 | O19: gen_ml_s69878_d10677_sp0 | P19: gen_ml_s69878_d10677_sp10 | Q19: gen_ml_s69878_d10677_sp20 | R19: gen_ml_s69878_d10677_sp30 | S19: gen_ml_s69878_d10677_sp40 | T19: gen_ml_s69878_d10677_sp50 | U19: gen_ml_s69878_d10677_sp60 | V19: gen_ml_s69878_d10677_sp70 | W19: gen_ml_s69878_d10677_sp80 | X19: gen_ml_s69878_d10677_sp90 | Y19: gen_ml_s69878_d10677_sp98 | Z19: ml_real_pivoted_na_s69878
B20: inp_file='test_news_s600_d384_sp0.csv' | C20: inp_file='test_news_s600_d384_sp0.csv' | D20: inp_file='test_news_s600_d3000_sp0.csv' | E20: inp_file='test_news_s600_d5000_sp0.csv' | F20: inp_file='test_news_s600_d7000_sp0.csv' | G20: inp_file='test_news_s600_d9000_sp0.csv' | H20: inp_file='test_news_s600_d10677_sp0.csv' | J20: inp_file='test_ml_s600_d384_sp0.csv' | K20: inp_file='test_ml_s600_d3000_sp0.csv' | L20: inp_file='test_ml_s600_d5000_sp0.csv' | M20: inp_file='test_ml_s600_d7000_sp0.csv' | N20: inp_file='test_ml_s600_d9000_sp0.csv' | O20: inp_file='test_ml_s600_d10677_sp0.csv' | P20: inp_file='test_ml_s600_d10677_sp0.csv' | Q20: inp_file='test_ml_s600_d10677_sp0.csv' | R20: inp_file='test_ml_s600_d10677_sp0.csv' | S20: inp_file='test_ml_s600_d10677_sp0.csv' | T20: inp_file='test_ml_s600_d10677_sp0.csv' | U20: inp_file='test_ml_s600_d10677_sp0.csv' | V20: inp_file='test_ml_s600_d10677_sp0.csv' | W20: inp_file='test_ml_s600_d10677_sp0.csv' | X20: inp_file='test_ml_s600_d10677_sp0.csv' | Y20: inp_file='test_ml_s600_d10677_sp0.csv' | Z20: inp_file='test_ml_s600_d10677_sp0.csv'
A21: 0 | B21: 5.5630972 | C21: 5.5905929 | D21: 13.882341 | E21: 16.356446 | F21: 23.304155 | G21: 26.247592 | H21: 29.724084 | J21: 6.30445 | K21: 11.166993 | L21: 16.663569 | M21: 19.996198 | N21: 24.915346 | O21: 31.516705 | P21: 32.037791 | Q21: 34.035975 | R21: 32.503138 | S21: 31.229098 | T21: 33.480891 | U21: 31.99327 | V21: 33.740546 | W21: 35.248415 | X21: 31.086065 | Y21: 30.761476 | Z21: 17.925665
A22: 1 | B22: 4.5697501 | C22: 4.8409219 | D22: 9.26001 | E22: 12.36538 | F22: 17.191664 | G22: 18.758904 | H22: 21.24402 | J22: 5.2510312 | K22: 8.604598 | L22: 11.295596 | M22: 13.780402 | N22: 16.828757 | O22: 17.880682 | P22: 18.87845 | Q22: 19.584211 | R22: 19.598977 | S22: 20.613445 | T22: 21.298633 | U22: 22.486842 | V22: 22.738208 | W22: 24.693327 | X22: 23.686776 | Y22: 23.84467 | Z22: 11.578898
A23: 2 | B23: 4.571902 | C23: 4.955116 | D23: 9.1733639 | E23: 12.403795 | F23: 15.38547 | G23: 18.76273 | H23: 21.068003 | J23: 5.61587 | K23: 9.2752559 | L23: 11.40226 | M23: 13.935207 | N23: 16.910734 | O23: 17.973024 | P23: 18.881784 | Q23: 19.857362 | R23: 19.689157 | S23: 20.543788 | T23: 21.209368 | U23: 21.752083 | V23: 22.263516 | W23: 23.106481 | X23: 23.690492 | Y23: 23.4609 | Z23: 11.536728
A24: 3 | B24: 4.4907839 | C24: 4.8520598 | D24: 9.267211 | E24: 12.450159 | F24: 15.370535 | G24: 18.743404 | H24: 21.117602 | J24: 4.8290422 | K24: 8.9573429 | L24: 11.257454 | M24: 13.898499 | N24: 16.821713 | O24: 21.308494 | P24: 18.91755 | Q24: 19.416532 | R24: 19.713667 | S24: 20.439226 | T24: 20.922966 | U24: 21.883486 | V24: 22.32296 | W24: 23.24792 | X24: 23.731453 | Y24: 23.911777 | Z24: 11.539087
A25: 4 | B25: 4.4606411 | C25: 4.8964982 | D25: 9.130918 | E25: 12.435377 | F25: 15.700455 | G25: 18.738733 | H25: 21.102538 | J25: 4.7815502 | K25: 8.710561 | L25: 11.422964 | M25: 13.746638 | N25: 16.866315 | O25: 17.872014 | P25: 18.865968 | Q25: 19.277329 | R25: 19.709005 | S25: 20.526855 | T25: 21.106075 | U25: 21.978496 | V25: 22.308254 | W25: 22.883382 | X25: 24.276509 | Y25: 23.588454 | Z25: 11.735871
A26: 5 | B26: 4.5917172 | C26: 4.9047389 | D26: 9.1112142 | E26: 12.385391 | F26: 15.339728 | G26: 18.76717 | H26: 21.184439 | J26: 4.752414 | K26: 9.5346739 | L26: 11.849216 | M26: 13.823599 | N26: 16.588846 | O26: 17.844493 | P26: 18.807104 | Q26: 19.331655 | R26: 19.671268 | S26: 20.356967 | T26: 20.986748 | U26: 21.741346 | V26: 22.281052 | W26: 23.067037 | X26: 23.55038 | Y26: 24.120888 | Z26: 11.406732
A27: avg | B27: =AVERAGE(B22:B26) -> 4.5369589 | C27: =AVERAGE(C22:C26) -> 4.889867 | D27: =AVERAGE(D22:D26) -> 9.1885434 | E27: =AVERAGE(E22:E26) -> 12.40802 | F27: =AVERAGE(F22:F26) -> 15.79757 | G27: =AVERAGE(G22:G26) -> 18.754188 | H27: =AVERAGE(H22:H26) -> 21.14332 | J27: =AVERAGE(J22:J26) -> 5.0459815 | K27: =AVERAGE(K22:K26) -> 9.0164864 | L27: =AVERAGE(L22:L26) -> 11.445498 | M27: =AVERAGE(M22:M26) -> 13.836869 | N27: =AVERAGE(N22:N26) -> 16.803273 | O27: =AVERAGE(O22:O26) -> 18.575741 | P27: =AVERAGE(P22:P26) -> 18.870171 | Q27: =AVERAGE(Q22:Q26) -> 19.493418 | ... Z27: =AVERAGE(Z22:Z26) -> 11.559463
A28: СІ 95% | B28: =_xlfn.CONFIDENCE.T(0.05, B29, 5) -> 0.071466601 | C28: =_xlfn.CONFIDENCE.T(0.05, C29, 5) -> 0.056722403 | D28: =_xlfn.CONFIDENCE.T(0.05, D29, 5) -> 0.089595699 | E28: =_xlfn.CONFIDENCE.T(0.05, E29, 5) -> 0.043334733 | F28: =_xlfn.CONFIDENCE.T(0.05, F29, 5) -> 0.98451007 | G28: =_xlfn.CONFIDENCE.T(0.05, G29, 5) -> 0.015444842 | H28: =_xlfn.CONFIDENCE.T(0.05, H29, 5) -> 0.087421563 | J28: =_xlfn.CONFIDENCE.T(0.05, J29, 5) -> 0.46871243 | K28: =_xlfn.CONFIDENCE.T(0.05, K29, 5) -> 0.48178334 | L28: =_xlfn.CONFIDENCE.T(0.05, L29, 5) -> 0.29330403 | M28: =_xlfn.CONFIDENCE.T(0.05, M29, 5) -> 0.098112737 | N28: =_xlfn.CONFIDENCE.T(0.05, N29, 5) -> 0.15519618 | O28: =_xlfn.CONFIDENCE.T(0.05, O29, 5) -> 1.897784 | P28: =_xlfn.CONFIDENCE.T(0.05, P29, 5) -> 0.049834346 | Q28: =_xlfn.CONFIDENCE.T(0.05, Q29, 5) -> 0.29084623 | ... Z28: =_xlfn.CONFIDENCE.T(0.05, Z29, 5) -> 0.14659575
A29: dev | B29: =_xlfn.STDEV.S(B22:B26) -> 0.057557118 | C29: =_xlfn.STDEV.S(C22:C26) -> 0.04568257 | D29: =_xlfn.STDEV.S(D22:D26) -> 0.072157765 | E29: =_xlfn.STDEV.S(E22:E26) -> 0.034900531 | F29: =_xlfn.STDEV.S(F22:F26) -> 0.79289572 | G29: =_xlfn.STDEV.S(G22:G26) -> 0.012438825 | H29: =_xlfn.STDEV.S(H22:H26) -> 0.070406779 | J29: =_xlfn.STDEV.S(J22:J26) -> 0.37748733 | K29: =_xlfn.STDEV.S(K22:K26) -> 0.38801427 | L29: =_xlfn.STDEV.S(L22:L26) -> 0.23621852 | M29: =_xlfn.STDEV.S(M22:M26) -> 0.079017139 | N29: =_xlfn.STDEV.S(N22:N26) -> 0.12499048 | O29: =_xlfn.STDEV.S(O22:O26) -> 1.5284199 | P29: =_xlfn.STDEV.S(P22:P26) -> 0.04013513 | Q29: =_xlfn.STDEV.S(Q22:Q26) -> 0.23423908 | ... Z29: =_xlfn.STDEV.S(Z22:Z26) -> 0.11806395
A30: min | B30: =MIN(B22:B26) -> 4.4606411 | C30: =MIN(C22:C26) -> 4.8409219 | D30: =MIN(D22:D26) -> 9.1112142 | E30: =MIN(E22:E26) -> 12.36538 | F30: =MIN(F22:F26) -> 15.339728 | G30: =MIN(G22:G26) -> 18.738733 | H30: =MIN(H22:H26) -> 21.068003 | J30: =MIN(J22:J26) -> 4.752414 | K30: =MIN(K22:K26) -> 8.604598 | L30: =MIN(L22:L26) -> 11.257454 | M30: =MIN(M22:M26) -> 13.746638 | N30: =MIN(N22:N26) -> 16.588846 | O30: =MIN(O22:O26) -> 17.844493 | P30: =MIN(P22:P26) -> 18.807104 | Q30: =MIN(Q22:Q26) -> 19.277329 | ... Z30: =MIN(Z22:Z26) -> 11.406732
A31: max | B31: =MAX(B22:B26) -> 4.5917172 | C31: =MAX(C22:C26) -> 4.955116 | D31: =MAX(D22:D26) -> 9.267211 | E31: =MAX(E22:E26) -> 12.450159 | F31: =MAX(F22:F26) -> 17.191664 | G31: =MAX(G22:G26) -> 18.76717 | H31: =MAX(H22:H26) -> 21.24402 | J31: =MAX(J22:J26) -> 5.61587 | K31: =MAX(K22:K26) -> 9.5346739 | L31: =MAX(L22:L26) -> 11.849216 | M31: =MAX(M22:M26) -> 13.935207 | N31: =MAX(N22:N26) -> 16.910734 | O31: =MAX(O22:O26) -> 21.308494 | P31: =MAX(P22:P26) -> 18.91755 | Q31: =MAX(Q22:Q26) -> 19.857362 | ... Z31: =MAX(Z22:Z26) -> 11.735871
B33: news_real_embedings_s69878 | C33: gen_news_s69878_d384_sp0 | D33: gen_news_s69878_d3000_sp0 | E33: en_news_s69878_d5000_sp0 | F33: gen_news_s69878_d7000_sp0 | G33: gen_news_s69878_d9000_sp0 | H33: gen_news_s69878_d10677_sp0 | J33: gen_ml_s69878_d384_sp0 | K33: gen_ml_s69878_d3000_sp0 | L33: gen_ml_s69878_d5000_sp0 | M33: gen_ml_s69878_d7000_sp0 | N33: gen_ml_s69878_d9000_sp0 | O33: gen_ml_s69878_d10677_sp0 | P33: gen_ml_s69878_d10677_sp10 | Q33: gen_ml_s69878_d10677_sp20 | R33: gen_ml_s69878_d10677_sp30 | S33: gen_ml_s69878_d10677_sp40 | T33: gen_ml_s69878_d10677_sp50 | U33: gen_ml_s69878_d10677_sp60 | V33: gen_ml_s69878_d10677_sp70 | W33: gen_ml_s69878_d10677_sp80 | X33: gen_ml_s69878_d10677_sp90 | Y33: gen_ml_s69878_d10677_sp98 | Z33: ml_real_pivoted_na_s69878
B34: inp_file='test_news_s600_d384_sp0.csv' | C34: inp_file='test_news_s600_d384_sp0.csv' | D34: inp_file='test_news_s600_d3000_sp0.csv' | E34: inp_file='test_news_s600_d5000_sp0.csv' | F34: inp_file='test_news_s600_d7000_sp0.csv' | G34: inp_file='test_news_s600_d9000_sp0.csv' | H34: inp_file='test_news_s600_d10677_sp0.csv' | J34: inp_file='test_ml_s600_d384_sp0.csv' | K34: inp_file='test_ml_s600_d3000_sp0.csv' | L34: inp_file='test_ml_s600_d5000_sp0.csv' | M34: inp_file='test_ml_s600_d7000_sp0.csv' | N34: inp_file='test_ml_s600_d9000_sp0.csv' | O34: inp_file='test_ml_s600_d10677_sp0.csv' | P34: inp_file='test_ml_s600_d10677_sp0.csv' | Q34: inp_file='test_ml_s600_d10677_sp0.csv' | R34: inp_file='test_ml_s600_d10677_sp0.csv' | S34: inp_file='test_ml_s600_d10677_sp0.csv' | T34: inp_file='test_ml_s600_d10677_sp0.csv' | U34: inp_file='test_ml_s600_d10677_sp0.csv' | V34: inp_file='test_ml_s600_d10677_sp0.csv' | W34: inp_file='test_ml_s600_d10677_sp0.csv' | X34: inp_file='test_ml_s600_d10677_sp0.csv' | Y34: inp_file='test_ml_s600_d10677_sp0.csv' | Z34: inp_file='test_ml_s600_d10677_sp0.csv'
A35: init client | B35: 5.3582039 | C35: 5.0992713 | D35: 87.70705 | E35: 173.6493 | F35: 317.80685 | G35: 499.91657 | H35: 614.87495 | J35: 5.4098289 | K35: 84.141637 | L35: 166.63399 | M35: 252.89731 | N35: 454.64532 | O35: 662.91851 | P35: 645.61853 | Q35: 627.04034 | R35: 673.31956 | S35: 632.42911 | T35: 579.16277 | U35: 543.60548 | V35: 564.60228 | W35: 463.38435 | X35: 426.03709 | Y35: 414.76378 | Z35: 505.50658
A36: 0 | B36: 17.376673 | C36: 17.38434 | D36: 146.36449 | E36: 251.81311 | F36: 328.78453 | G36: 429.24914 | H36: 577.40338 | J36: 17.246827 | K36: 145.45756 | L36: 234.92377 | M36: 325.29072 | N36: 441.06619 | O36: 571.62736 | P36: 589.07944 | Q36: 575.8245 | R36: 561.21894 | S36: 590.57014 | T36: 561.23504 | U36: 564.33447 | V36: 536.18789 | W36: 532.67808 | X36: 578.06979 | Y36: 646.70063 | Z36: 539.68273
A37: 1 | B37: 17.378597 | C37: 17.352392 | D37: 144.9482 | E37: 235.59115 | F37: 307.68553 | G37: 436.97497 | H37: 496.87302 | J37: 17.224217 | K37: 147.4751 | L37: 239.69908 | M37: 326.42595 | N37: 412.0934 | O37: 529.91022 | P37: 537.49719 | Q37: 523.33984 | R37: 511.99496 | S37: 521.95817 | T37: 513.94931 | U37: 516.47221 | V37: 506.41122 | W37: 501.62881 | X37: 520.14987 | Y37: 625.9912 | Z37: 526.2067
A38: 2 | B38: 17.326408 | C38: 17.423638 | D38: 145.93257 | E38: 230.95614 | F38: 316.1296 | G38: 472.00778 | H38: 519.74947 | J38: 17.209167 | K38: 144.53407 | L38: 231.66098 | M38: 324.64154 | N38: 420.04627 | O38: 518.6787 | P38: 544.23399 | Q38: 500.03169 | R38: 505.41436 | S38: 500.92802 | T38: 507.54138 | U38: 506.36643 | V38: 505.23348 | W38: 496.98323 | X38: 527.62345 | Y38: 634.31919 | Z38: 527.14834
A39: 3 | B39: 17.313839 | C39: 17.414467 | D39: 145.51356 | E39: 222.82654 | F39: 323.25333 | G39: 445.63426 | H39: 507.67966
A40: 4 | B40: 17.343296 | C40: 17.438707 | D40: 147.14936 | E40: 227.71865 | F40: 323.52134 | G40: 438.42441 | H40: 504.01428
A41: 5 | B41: 17.357347 | C41: 17.381112 | D41: 150.97954 | E41: 233.47573 | F41: 323.75784 | G41: 399.46553 | H41: 495.35321
A42: avg | B42: =AVERAGE(B37:B41) -> 17.343897 | C42: =AVERAGE(C37:C41) -> 17.402063 | D42: =AVERAGE(D37:D41) -> 146.90465 | E42: =AVERAGE(E37:E41) -> 230.11364 | F42: =AVERAGE(F37:F41) -> 318.86953 | G42: =AVERAGE(G37:G41) -> 438.50139 | H42: =AVERAGE(H37:H41) -> 504.73393 | J42: =AVERAGE(J37:J41) -> 17.216692 | K42: =AVERAGE(K37:K41) -> 146.00459 | L42: =AVERAGE(L37:L41) -> 235.68003 | M42: =AVERAGE(M37:M41) -> 325.53374 | N42: =AVERAGE(N37:N41) -> 416.06984 | O42: =AVERAGE(O37:O41) -> 524.29446 | P42: =AVERAGE(P37:P41) -> 540.86559 | Q42: =AVERAGE(Q37:Q41) -> 511.68577 | ... Z42: =AVERAGE(Z37:Z41) -> 526.67752
...

Sheet real vs gen
A1: 100 nn
B2: real | C2: real | D2: gen | E2: gen | F2: real | G2: real | H2: gen | I2: gen
B3: chroma | C3: qdrant | D3: chroma | E3: qdrant | F3: chroma | G3: qdrant | H3: chroma | I3: qdrant
B4: news | C4: news | D4: news | E4: news | F4: ml | G4: ml | H4: ml | I4: ml
A5: 1 | B5: =RESULTS!B7 -> 0.3223362 | C5: =RESULTS!B72 -> 0.84811497 | D5: =RESULTS!C7 -> 0.36156082 | E5: =RESULTS!C72 -> 0.84147286 | F5: =RESULTS!Z7 -> 0.93085408 | G5: =RESULTS!Z72 -> 2.7674041 | H5: =RESULTS!Y7 -> 2.2450871 | I5: =RESULTS!Y72 -> 5.7123342
A6: 2 | B6: =RESULTS!B8 -> 0.31631088 | C6: =RESULTS!B73 -> 0.67576885 | D6: =RESULTS!C8 -> 0.36437106 | E6: =RESULTS!C73 -> 0.74235797 | F6: =RESULTS!Z8 -> 0.84003568 | G6: =RESULTS!Z73 -> 2.817683 | H6: =RESULTS!Y8 -> 2.0994639 | I6: =RESULTS!Y73 -> 5.8329961
A7: 3 | B7: =RESULTS!B9 -> 0.31699419 | C7: =RESULTS!B74 -> 0.69715977 | D7: =RESULTS!C9 -> 0.36489701 | E7: =RESULTS!C74 -> 0.73850513 | F7: =RESULTS!Z9 -> 0.81713176 | G7: =RESULTS!Z74 -> 2.760802 | H7: =RESULTS!Y9 -> 1.931169 | I7: =RESULTS!Y74 -> 5.625962
A8: 4 | B8: =RESULTS!B10 -> 0.3118248 | C8: =RESULTS!B75 -> 0.67136002 | D8: =RESULTS!C10 -> 0.36478996 | E8: =RESULTS!C75 -> 0.75494766 | F8: =RESULTS!Z10 -> 0.81175399 | G8: =RESULTS!Z75 -> 2.7569609 | H8: =RESULTS!Y10 -> 1.7990851 | I8: =RESULTS!Y75 -> 5.6397502
A9: 5 | B9: =RESULTS!B11 -> 0.31072402 | C9: =RESULTS!B76 -> 0.67367291 | D9: =RESULTS!C11 -> 0.34864688 | E9: =RESULTS!C76 -> 0.72939968 | F9: =RESULTS!Z11 -> 0.82955694 | G9: =RESULTS!Z76 -> 2.7551932 | H9: =RESULTS!Y11 -> 1.8121519 | I9: =RESULTS!Y76 -> 5.6351759
A10: AVG | B10: =RESULTS!B12 -> 0.31563802 | C10: =RESULTS!B77 -> 0.7132153 | D10: =RESULTS!C12 -> 0.36085315 | E10: =RESULTS!C77 -> 0.76133666 | F10: =RESULTS!Z12 -> 0.84586649 | G10: =RESULTS!Z77 -> 2.7716086 | H10: =RESULTS!Y12 -> 1.9773914 | I10: =RESULTS!Y77 -> 5.6892437
A11: STDEV | B11: =RESULTS!B14 -> 0.0046326442 | C11: =RESULTS!B79 -> 0.076114062 | D11: =RESULTS!C14 -> 0.0069591822 | E11: =RESULTS!C79 -> 0.045727647 | F11: =RESULTS!Z14 -> 0.048765352 | G11: =RESULTS!Z79 -> 0.02617885 | H11: =RESULTS!Y14 -> 0.19222151 | I11: =RESULTS!Y79 -> 0.087429151
A12: MIN | B12: =RESULTS!B15 -> 0.31072402 | C12: =RESULTS!B80 -> 0.67136002 | D12: =RESULTS!C15 -> 0.34864688 | E12: =RESULTS!C80 -> 0.72939968 | F12: =RESULTS!Z15 -> 0.81175399 | G12: =RESULTS!Z80 -> 2.7551932 | H12: =RESULTS!Y15 -> 1.7990851 | I12: =RESULTS!Y80 -> 5.625962
A13: MAX | B13: =RESULTS!B16 -> 0.3223362 | C13: =RESULTS!B81 -> 0.84811497 | D13: =RESULTS!C16 -> 0.36489701 | E13: =RESULTS!C81 -> 0.84147286 | F13: =RESULTS!Z16 -> 0.93085408 | G13: =RESULTS!Z81 -> 2.817683 | H13: =RESULTS!Y16 -> 2.2450871 | I13: =RESULTS!Y81 -> 5.8329961
A15: 2500nn
B16: real | C16: real | D16: gen | E16: gen | F16: real | G16: real | H16: gen | I16: gen
B17: chroma | C17: qdrant | D17: chroma | E17: qdrant | F17: chroma | G17: qdrant | H17: chroma | I17: qdrant
B18: news | C18: news | D18: news | E18: news | F18: ml | G18: ml | H18: ml | I18: ml
A19: 1 | B19: =RESULTS!B22 -> 4.5697501 | C19: =RESULTS!B87 -> 3.2386773 | D19: =RESULTS!C22 -> 4.8409219 | E19: =RESULTS!C87 -> 4.1187909 | F19: =RESULTS!Z22 -> 11.578898 | G19: =RESULTS!Z87 -> 6.7850599 | H19: =RESULTS!Y22 -> 23.84467 | I19: =RESULTS!Y87 -> 17.085994
A20: 2 | B20: =RESULTS!B23 -> 4.571902 | C20: =RESULTS!B88 -> 3.1833999 | D20: =RESULTS!C23 -> 4.955116 | E20: =RESULTS!C88 -> 3.7579341 | F20: =RESULTS!Z23 -> 11.536728 | G20: =RESULTS!Z88 -> 6.7067182 | H20: =RESULTS!Y23 -> 23.4609 | I20: =RESULTS!Y88 -> 17.084601
A21: 3 | B21: =RESULTS!B24 -> 4.4907839 | C21: =RESULTS!B89 -> 3.1977398 | D21: =RESULTS!C24 -> 4.8520598 | E21: =RESULTS!C89 -> 3.3446791 | F21: =RESULTS!Z24 -> 11.539087 | G21: =RESULTS!Z89 -> 6.6806049 | H21: =RESULTS!Y24 -> 23.911777 | I21: =RESULTS!Y89 -> 17.129152
A22: 4 | B22: =RESULTS!B25 -> 4.4606411 | C22: =RESULTS!B90 -> 3.1556182 | D22: =RESULTS!C25 -> 4.8964982 | E22: =RESULTS!C90 -> 3.186173 | F22: =RESULTS!Z25 -> 11.735871 | G22: =RESULTS!Z90 -> 6.819037 | H22: =RESULTS!Y25 -> 23.588454 | I22: =RESULTS!Y90 -> 17.048249
A23: 5 | B23: =RESULTS!B26 -> 4.5917172 | C23: =RESULTS!B91 -> 3.220958 | D23: =RESULTS!C26 -> 4.9047389 | E23: =RESULTS!C91 -> 3.1800282 | F23: =RESULTS!Z26 -> 11.406732 | G23: =RESULTS!Z91 -> 6.6396842 | H23: =RESULTS!Y26 -> 24.120888 | I23: =RESULTS!Y91 -> 17.143667
A24: AVG | B24: =RESULTS!B27 -> 4.5369589 | C24: =RESULTS!B92 -> 3.1992786 | D24: =RESULTS!C27 -> 4.889867 | E24: =RESULTS!C92 -> 3.517521 | F24: =RESULTS!Z27 -> 11.559463 | G24: =RESULTS!Z92 -> 6.7262208 | H24: =RESULTS!Y27 -> 23.785338 | I24: =RESULTS!Y92 -> 17.098333
A25: STDEV | B25: =RESULTS!B29 -> 0.057557118 | C25: =RESULTS!B94 -> 0.032337991 | D25: =RESULTS!C29 -> 0.04568257 | E25: =RESULTS!C94 -> 0.41014971 | F25: =RESULTS!Z29 -> 0.11806395 | G25: =RESULTS!Z94 -> 0.074206846 | H25: =RESULTS!Y29 -> 0.26273773 | I25: =RESULTS!Y94 -> 0.038256488
A26: MIN | B26: =RESULTS!B30 -> 4.4606411 | C26: =RESULTS!B95 -> 3.1556182 | D26: =RESULTS!C30 -> 4.8409219 | E26: =RESULTS!C95 -> 3.1800282 | F26: =RESULTS!Z30 -> 11.406732 | G26: =RESULTS!Z95 -> 6.6396842 | H26: =RESULTS!Y30 -> 23.4609 | I26: =RESULTS!Y95 -> 17.048249
A27: MAX | B27: =RESULTS!B31 -> 4.5917172 | C27: =RESULTS!B96 -> 3.2386773 | D27: =RESULTS!C31 -> 4.955116 | E27: =RESULTS!C96 -> 4.1187909 | F27: =RESULTS!Z31 -> 11.735871 | G27: =RESULTS!Z96 -> 6.819037 | H27: =RESULTS!Y31 -> 24.120888 | I27: =RESULTS!Y96 -> 17.143667

Sheet sparsity
A3: 100nn
A4: sp | B4: 0 | C4: 10 | D4: 20 | E4: 30 | F4: 40 | G4: 50 | H4: 60 | I4: 70 | J4: 80 | K4: 90 | L4: 98.66
A5: chroma | B5: =RESULTS!O12 -> 1.8789813 | C5: =RESULTS!P12 -> 1.681182 | D5: =RESULTS!Q12 -> 1.8815799 | E5: =RESULTS!R12 -> 1.9089429 | F5: =RESULTS!S12 -> 1.954364 | G5: =RESULTS!T12 -> 2.0002378 | H5: =RESULTS!U12 -> 1.8784245 | I5: =RESULTS!V12 -> 2.0402544 | ... L5: =RESULTS!Y12 -> 1.9773914
A6: СІ 95% | B6: =RESULTS!O13 -> 0.16225244 | C6: =RESULTS!P13 -> 0.027653481 | D6: =RESULTS!Q13 -> 0.26679882 | E6: =RESULTS!R13 -> 0.21217418 | F6: =RESULTS!S13 -> 0.10910565 | G6: =RESULTS!T13 -> 0.14832582 | H6: =RESULTS!U13 -> 0.054416613 | I6: =RESULTS!V13 -> 0.27915703 | ... L6: =RESULTS!Y13 -> 0.23867453
A7: qdrant | B7: =RESULTS!O77 -> 4.6890299 | C7: =RESULTS!P77 -> 4.63988 | D7: =RESULTS!Q77 -> 4.6847342 | E7: =RESULTS!R77 -> 4.7981655 | F7: =RESULTS!S77 -> 4.9018929 | G7: =RESULTS!T77 -> 5.0097172 | H7: =RESULTS!U77 -> 5.2976588 | I7: =RESULTS!V77 -> 5.226661 | ... L7: =RESULTS!Y77 -> 5.6892437
A8: СІ 95% | B8: =RESULTS!O78 -> 0.065167511 | C8: =RESULTS!P78 -> 0.093920935 | D8: =RESULTS!Q78 -> 0.052736214 | E8: =RESULTS!R78 -> 0.05802544 | F8: =RESULTS!S78 -> 0.056234902 | G8: =RESULTS!T78 -> 0.087143223 | H8: =RESULTS!U78 -> 0.53185609 | I8: =RESULTS!V78 -> 0.071510323 | ... L8: =RESULTS!Y78 -> 0.10855763
A14: 2500nn
A15: sp | B15: 0 | C15: 10 | D15: 20 | E15: 30 | F15: 40 | G15: 50 | H15: 60 | I15: 70 | J15: 80 | K15: 90 | L15: 98.66
A16: chroma | B16: =RESULTS!O27 -> 18.575741 | C16: =RESULTS!P27 -> 18.870171 | D16: =RESULTS!Q27 -> 19.493418 | E16: =RESULTS!R27 -> 19.676415 | F16: =RESULTS!S27 -> 20.496056 | G16: =RESULTS!T27 -> 21.104758 | H16: =RESULTS!U27 -> 21.96845 | I16: =RESULTS!V27 -> 22.382798 | ... L16: =RESULTS!Y27 -> 23.785338
A17: СІ 95% | B17: =RESULTS!O28 -> 1.897784 | C17: =RESULTS!P28 -> 0.049834346 | D17: =RESULTS!Q28 -> 0.29084623 | E17: =RESULTS!R28 -> 0.057691571 | F17: =RESULTS!S28 -> 0.12351649 | G17: =RESULTS!T28 -> 0.19186344 | H17: =RESULTS!U28 -> 0.37989676 | I17: =RESULTS!V28 -> 0.24835936 | ... L17: =RESULTS!Y28 -> 0.32623197
A18: qdrant | B18: =RESULTS!O92 -> 12.097707 | C18: =RESULTS!P92 -> 12.192801 | D18: =RESULTS!Q92 -> 12.338703 | E18: =RESULTS!R92 -> 12.787035 | F18: =RESULTS!S92 -> 13.354182 | G18: =RESULTS!T92 -> 13.824459 | H18: =RESULTS!U92 -> 14.112197 | I18: =RESULTS!V92 -> 15.037061 | ... L18: =RESULTS!Y92 -> 17.098333
A19: СІ 95% | B19: =RESULTS!O93 -> 0.089064561 | C19: =RESULTS!P93 -> 0.034478463 | D19: =RESULTS!Q93 -> 0.089176378 | E19: =RESULTS!R93 -> 0.084701763 | F19: =RESULTS!S93 -> 0.08416814 | G19: =RESULTS!T93 -> 0.22650798 | H19: =RESULTS!U93 -> 0.26719214 | I19: =RESULTS!V93 -> 0.10975412 | ... L19: =RESULTS!Y93 -> 0.047501703

Sheet ml vs news
A1: 100nn
B2: Chroma | C2: Chroma | D2: Chroma | E2: Chroma | G2: Qdrant | H2: Qdrant | I2: Qdrant | J2: Qdrant
B3: News 10677 | C3: ML sp0 | D3: ML sp50 | E3: ML sp90 | G3: News 10677 | H3: ML sp0 | I3: ML sp50 | J3: ML sp90
A4: 1 | B4: =RESULTS!H7 -> 2.0299969 | C4: =RESULTS!O7 -> 2.0804849 | D4: =RESULTS!T7 -> 2.1931708 | E4: =RESULTS!X7 -> 2.3449881 | F4: 1 | G4: =RESULTS!H72 -> 5.3983762 | H4: =RESULTS!O72 -> 4.7450213 | I4: =RESULTS!T72 -> 5.1201642 | J4: =RESULTS!X72 -> 5.5966918
A5: 2 | B5: =RESULTS!H8 -> 2.2961738 | C5: =RESULTS!O8 -> 1.9372349 | D5: =RESULTS!T8 -> 2.0309031 | E5: =RESULTS!X8 -> 1.9982951 | F5: 2 | G5: =RESULTS!H73 -> 5.3817689 | H5: =RESULTS!O73 -> 4.7380991 | I5: =RESULTS!T73 -> 4.9643941 | J5: =RESULTS!X73 -> 5.5701039
A6: 3 | B6: =RESULTS!H9 -> 1.5648718 | C6: =RESULTS!O9 -> 1.8218522 | D6: =RESULTS!T9 -> 1.9561594 | E6: =RESULTS!X9 -> 2.1413822 | F6: 3 | G6: =RESULTS!H74 -> 5.4218361 | H6: =RESULTS!O74 -> 4.6358242 | I6: =RESULTS!T74 -> 4.9617069 | J6: =RESULTS!X74 -> 5.553581
A7: 4 | B7: =RESULTS!H10 -> 1.585043 | C7: =RESULTS!O10 -> 1.7936692 | D7: =RESULTS!T10 -> 1.931216 | E7: =RESULTS!X10 -> 2.0058959 | F7: 4 | G7: =RESULTS!H75 -> 5.4274471 | H7: =RESULTS!O75 -> 4.6376059 | I7: =RESULTS!T75 -> 5.0398791 | J7: =RESULTS!X75 -> 5.5230432
A8: 5 | B8: =RESULTS!H11 -> 1.8753531 | C8: =RESULTS!O11 -> 1.7616651 | D8: =RESULTS!T11 -> 1.88974 | E8: =RESULTS!X11 -> 3.1156113 | F8: 5 | G8: =RESULTS!H76 -> 5.3890889 | H8: =RESULTS!O76 -> 4.6885989 | I8: =RESULTS!T76 -> 4.9624419 | J8: =RESULTS!X76 -> 5.5389159
A9: AVG | B9: =RESULTS!H12 -> 1.8702877 | C9: =RESULTS!O12 -> 1.8789813 | D9: =RESULTS!T12 -> 2.0002378 | E9: =RESULTS!X12 -> 2.3212345 | F9: AVG | G9: =RESULTS!H77 -> 5.4037035 | H9: =RESULTS!O77 -> 4.6890299 | I9: =RESULTS!T77 -> 5.0097172 | J9: =RESULTS!X77 -> 5.5564672
A10: STDEV | B10: =RESULTS!H14 -> 0.30885073 | C10: =RESULTS!O14 -> 0.13067339 | D10: =RESULTS!T14 -> 0.1194573 | E10: =RESULTS!X14 -> 0.46574509 | F10: STDEV | G10: =RESULTS!H79 -> 0.020097527 | H10: =RESULTS!O79 -> 0.052484014 | I10: =RESULTS!T79 -> 0.070182613 | J10: =RESULTS!X79 -> 0.028449637
A11: MIN | B11: =RESULTS!H15 -> 1.5648718 | C11: =RESULTS!O15 -> 1.7616651 | D11: =RESULTS!T15 -> 1.88974 | E11: =RESULTS!X15 -> 1.9982951 | F11: MIN | G11: =RESULTS!H80 -> 5.3817689 | H11: =RESULTS!O80 -> 4.6358242 | I11: =RESULTS!T80 -> 4.9617069 | J11: =RESULTS!X80 -> 5.5230432
A12: MAX | B12: =RESULTS!H16 -> 2.2961738 | C12: =RESULTS!O16 -> 2.0804849 | D12: =RESULTS!T16 -> 2.1931708 | E12: =RESULTS!X16 -> 3.1156113 | F12: MAX | G12: =RESULTS!H81 -> 5.4274471 | H12: =RESULTS!O81 -> 4.7450213 | I12: =RESULTS!T81 -> 5.1201642 | J12: =RESULTS!X81 -> 5.5966918
A14: 2500nn
B15: Chroma | C15: Chroma | D15: Chroma | E15: Chroma | G15: Qdrant | H15: Qdrant | I15: Qdrant | J15: Qdrant
B16: News 10677 | C16: ML sp0 | D16: ML sp50 | E16: ML sp90 | G16: News 10677 | H16: ML sp0 | I16: ML sp50 | J16: ML sp90
A17: 1 | B17: =RESULTS!H22 -> 21.24402 | C17: =RESULTS!O22 -> 17.880682 | D17: =RESULTS!T22 -> 21.298633 | E17: =RESULTS!X22 -> 23.686776 | F17: 1 | G17: =RESULTS!H87 -> 15.204995 | H17: =RESULTS!O87 -> 12.174844 | I17: =RESULTS!T87 -> 13.883086 | J17: =RESULTS!X87 -> 16.36262
A18: 2 | B18: =RESULTS!H23 -> 21.068003 | C18: =RESULTS!O23 -> 17.973024 | D18: =RESULTS!T23 -> 21.209368 | E18: =RESULTS!X23 -> 23.690492 | F18: 2 | G18: =RESULTS!H88 -> 15.026822 | H18: =RESULTS!O88 -> 11.989682 | I18: =RESULTS!T88 -> 13.662375 | J18: =RESULTS!X88 -> 16.449389
A19: 3 | B19: =RESULTS!H24 -> 21.117602 | C19: =RESULTS!O24 -> 21.308494 | D19: =RESULTS!T24 -> 20.922966 | E19: =RESULTS!X24 -> 23.731453 | F19: 3 | G19: =RESULTS!H89 -> 15.261606 | H19: =RESULTS!O89 -> 12.124683 | I19: =RESULTS!T89 -> 13.685672 | J19: =RESULTS!X89 -> 16.434997
A20: 4 | B20: =RESULTS!H25 -> 21.102538 | C20: =RESULTS!O25 -> 17.872014 | D20: =RESULTS!T25 -> 21.106075 | E20: =RESULTS!X25 -> 24.276509 | F20: 4 | G20: =RESULTS!H90 -> 15.132642 | H20: =RESULTS!O90 -> 12.0663 | I20: =RESULTS!T90 -> 14.111112 | J20: =RESULTS!X90 -> 16.641929
A21: 5 | B21: =RESULTS!H26 -> 21.184439 | C21: =RESULTS!O26 -> 17.844493 | D21: =RESULTS!T26 -> 20.986748 | E21: =RESULTS!X26 -> 23.55038 | F21: 5 | G21: =RESULTS!H91 -> 14.796758 | H21: =RESULTS!O91 -> 12.133023 | I21: =RESULTS!T91 -> 13.780048 | J21: =RESULTS!X91 -> 16.666323
A22: AVG | B22: =RESULTS!H27 -> 21.14332 | C22: =RESULTS!O27 -> 18.575741 | D22: =RESULTS!T27 -> 21.104758 | E22: =RESULTS!X27 -> 23.787122 | F22: AVG | G22: =RESULTS!H92 -> 15.084565 | H22: =RESULTS!O92 -> 12.097707 | I22: =RESULTS!T92 -> 13.824459 | J22: =RESULTS!X92 -> 16.511052
A23: STDEV | B23: =RESULTS!H29 -> 0.070406779 | C23: =RESULTS!O29 -> 1.5284199 | D23: =RESULTS!T29 -> 0.15452122 | E23: =RESULTS!X29 -> 0.28198055 | F23: STDEV | G23: =RESULTS!H94 -> 0.18325207 | H23: =RESULTS!O94 -> 0.071730002 | I23: =RESULTS!T94 -> 0.18242293 | J23: =RESULTS!X94 -> 0.13495992
A24: MIN | B24: =RESULTS!H30 -> 21.068003 | C24: =RESULTS!O30 -> 17.844493 | D24: =RESULTS!T30 -> 20.922966 | E24: =RESULTS!X30 -> 23.55038 | F24: MIN | G24: =RESULTS!H95 -> 14.796758 | H24: =RESULTS!O95 -> 11.989682 | I24: =RESULTS!T95 -> 13.662375 | J24: =RESULTS!X95 -> 16.36262
A25: MAX | B25: =RESULTS!H31 -> 21.24402 | C25: =RESULTS!O31 -> 21.308494 | D25: =RESULTS!T31 -> 21.298633 | E25: =RESULTS!X31 -> 24.276509 | F25: MAX | G25: =RESULTS!H96 -> 15.261606 | H25: =RESULTS!O96 -> 12.174844 | I25: =RESULTS!T96 -> 14.111112 | J25: =RESULTS!X96 -> 16.666323

Sheet dimentionality
A1: 100nn
A2: dim | B2: 384 | C2: 3000 | D2: 5000 | E2: 7000 | F2: 9000 | G2: 10677
A3: chroma, news | B3: =RESULTS!C12 -> 0.36085315 | C3: =RESULTS!D12 -> 0.84696765 | D3: =RESULTS!E12 -> 1.0491234 | E3: =RESULTS!F12 -> 1.2784922 | F3: =RESULTS!G12 -> 1.6245978 | G3: =RESULTS!H12 -> 1.8702877
A4: СІ 95% | B4: =RESULTS!C13 -> 0.008640966 | C4: =RESULTS!D13 -> 0.15944947 | D4: =RESULTS!E13 -> 0.048332973 | E4: =RESULTS!F13 -> 0.025763189 | F4: =RESULTS!G13 -> 0.056844999 | G4: =RESULTS!H13 -> 0.38348884
A5: chroma, ml | B5: =RESULTS!J12 -> 0.40299463 | C5: =RESULTS!K12 -> 0.71448059 | D5: =RESULTS!L12 -> 0.97633824 | E5: =RESULTS!M12 -> 1.2167758 | F5: =RESULTS!N12 -> 1.5715208 | G5: =RESULTS!O12 -> 1.8789813
A6: СІ 95% | B6: =RESULTS!J13 -> 0.047262167 | C6: =RESULTS!K13 -> 0.010960236 | D6: =RESULTS!L13 -> 0.026162015 | E6: =RESULTS!M13 -> 0.021396851 | F6: =RESULTS!N13 -> 0.048688892 | G6: =RESULTS!O13 -> 0.16225244
A7: qdrant, news | B7: =RESULTS!C77 -> 0.76133666 | C7: =RESULTS!D77 -> 1.9653762 | D7: =RESULTS!E77 -> 2.8739592 | E7: =RESULTS!F77 -> 3.7767848 | F7: =RESULTS!G77 -> 4.7450544 | G7: =RESULTS!H77 -> 5.4037035
A8: СІ 95% | B8: =RESULTS!C78 -> 0.056778373 | C8: =RESULTS!D78 -> 0.039444362 | D8: =RESULTS!E78 -> 0.057561998 | E8: =RESULTS!F78 -> 0.036517291 | F8: =RESULTS!G78 -> 0.033966056 | G8: =RESULTS!H78 -> 0.024954375
A9: qdrant, ml | B9: =RESULTS!J77 -> 0.72319179 | C9: =RESULTS!K77 -> 1.7365489 | D9: =RESULTS!L77 -> 2.577049 | E9: =RESULTS!M77 -> 3.2657415 | F9: =RESULTS!N77 -> 4.0226852 | G9: =RESULTS!O77 -> 4.6890299
A10: СІ 95% | B10: =RESULTS!J78 -> 0.018883938 | C10: =RESULTS!K78 -> 0.029726977 | D10: =RESULTS!L78 -> 0.072530574 | E10: =RESULTS!M78 -> 0.051841158 | F10: =RESULTS!N78 -> 0.055660876 | G10: =RESULTS!O78 -> 0.065167511
A12: 2500nn
A13: dim | B13: 384 | C13: 3000 | D13: 5000 | E13: 7000 | F13: 9000 | G13: 10677
A14: chroma, news | B14: =RESULTS!C27 -> 4.889867 | C14: =RESULTS!D27 -> 9.1885434 | D14: =RESULTS!E27 -> 12.40802 | E14: =RESULTS!F27 -> 15.79757 | F14: =RESULTS!G27 -> 18.754188 | G14: =RESULTS!H27 -> 21.14332
A15: СІ 95% | B15: =RESULTS!C28 -> 0.056722403 | C15: =RESULTS!D28 -> 0.089595699 | D15: =RESULTS!E28 -> 0.043334733 | E15: =RESULTS!F28 -> 0.98451007 | F15: =RESULTS!G28 -> 0.015444842 | G15: =RESULTS!H28 -> 0.087421563
A16: chroma, ml | B16: =RESULTS!J27 -> 5.0459815 | C16: =RESULTS!K27 -> 9.0164864 | D16: =RESULTS!L27 -> 11.445498 | E16: =RESULTS!M27 -> 13.836869 | F16: =RESULTS!N27 -> 16.803273 | G16: =RESULTS!O27 -> 18.575741
A17: СІ 95% | B17: =RESULTS!J28 -> 0.46871243 | C17: =RESULTS!K28 -> 0.48178334 | D17: =RESULTS!L28 -> 0.29330403 | E17: =RESULTS!M28 -> 0.098112737 | F17: =RESULTS!N28 -> 0.15519618 | G17: =RESULTS!O28 -> 1.897784
A18: qdrant, news | B18: =RESULTS!C92 -> 3.517521 | C18: =RESULTS!D92 -> 5.9774671 | D18: =RESULTS!E92 -> 8.2970446 | E18: =RESULTS!F92 -> 10.515592 | F18: =RESULTS!G92 -> 13.043038 | G18: =RESULTS!H92 -> 15.084565
A19: СІ 95% | B19: =RESULTS!C93 -> 0.50926813 | C19: =RESULTS!D93 -> 0.077017722 | D19: =RESULTS!E93 -> 0.096403004 | E19: =RESULTS!F93 -> 0.12378629 | F19: =RESULTS!G93 -> 0.075212864 | G19: =RESULTS!H93 -> 0.2275375
A20: qdrant, ml | B20: =RESULTS!J92 -> 3.0557368 | C20: =RESULTS!K92 -> 5.277218 | D20: =RESULTS!L92 -> 7.0624048 | E20: =RESULTS!M92 -> 8.8974627 | F20: =RESULTS!N92 -> 10.745085 | G20: =RESULTS!O92 -> 12.097707
A21: СІ 95% | B21: =RESULTS!J93 -> 0.046851044 | C21: =RESULTS!K93 -> 0.040786917 | D21: =RESULTS!L93 -> 0.037625224 | E21: =RESULTS!M93 -> 0.078473286 | F21: =RESULTS!N93 -> 0.079594919 | G21: =RESULTS!O93 -> 0.089064561
